2024-03-29 16:56:19.413197
<class 'openai.APITimeoutError'>
APITimeoutError('Request timed out.')
  File "D:\argsdata\TEST\ft_gpt3.5_test.py", line 48, in <module>
    response = client.chat.completions.create(

  File "C:\Users\47131\.conda\envs\DoT\lib\site-packages\openai\_utils\_utils.py", line 275, in wrapper
    return func(*args, **kwargs)

  File "C:\Users\47131\.conda\envs\DoT\lib\site-packages\openai\resources\chat\completions.py", line 667, in create
    return self._post(

  File "C:\Users\47131\.conda\envs\DoT\lib\site-packages\openai\_base_client.py", line 1208, in post
    return cast(ResponseT, self.request(cast_to, opts, stream=stream, stream_cls=stream_cls))

  File "C:\Users\47131\.conda\envs\DoT\lib\site-packages\openai\_base_client.py", line 897, in request
    return self._request(

  File "C:\Users\47131\.conda\envs\DoT\lib\site-packages\openai\_base_client.py", line 950, in _request
    return self._retry_request(

  File "C:\Users\47131\.conda\envs\DoT\lib\site-packages\openai\_base_client.py", line 1021, in _retry_request
    return self._request(

  File "C:\Users\47131\.conda\envs\DoT\lib\site-packages\openai\_base_client.py", line 935, in _request
    return self._retry_request(

  File "C:\Users\47131\.conda\envs\DoT\lib\site-packages\openai\_base_client.py", line 1021, in _retry_request
    return self._request(

  File "C:\Users\47131\.conda\envs\DoT\lib\site-packages\openai\_base_client.py", line 945, in _request
    raise APITimeoutError(request=request) from err


