2024-03-29 22:33:21.997465
<class 'ConnectionError'>
ConnectionError('Can\'t access server at https://arg-quality.debater.res.ibm.com/score/. Exception: Traceback (most recent call last):\n  File "C:\\Users\\94427\\anaconda3\\envs\\DoT\\lib\\site-packages\\urllib3\\connectionpool.py", line 467, in _make_request\n    self._validate_conn(conn)\n  File "C:\\Users\\94427\\anaconda3\\envs\\DoT\\lib\\site-packages\\urllib3\\connectionpool.py", line 1099, in _validate_conn\n    conn.connect()\n  File "C:\\Users\\94427\\anaconda3\\envs\\DoT\\lib\\site-packages\\urllib3\\connection.py", line 653, in connect\n    sock_and_verified = _ssl_wrap_socket_and_match_hostname(\n  File "C:\\Users\\94427\\anaconda3\\envs\\DoT\\lib\\site-packages\\urllib3\\connection.py", line 806, in _ssl_wrap_socket_and_match_hostname\n    ssl_sock = ssl_wrap_socket(\n  File "C:\\Users\\94427\\anaconda3\\envs\\DoT\\lib\\site-packages\\urllib3\\util\\ssl_.py", line 465, in ssl_wrap_socket\n    ssl_sock = _ssl_wrap_socket_impl(sock, context, tls_in_tls, server_hostname)\n  File "C:\\Users\\94427\\anaconda3\\envs\\DoT\\lib\\site-packages\\urllib3\\util\\ssl_.py", line 509, in _ssl_wrap_socket_impl\n    return ssl_context.wrap_socket(sock, server_hostname=server_hostname)\n  File "C:\\Users\\94427\\anaconda3\\envs\\DoT\\lib\\ssl.py", line 512, in wrap_socket\n    return self.sslsocket_class._create(\n  File "C:\\Users\\94427\\anaconda3\\envs\\DoT\\lib\\ssl.py", line 1070, in _create\n    self.do_handshake()\n  File "C:\\Users\\94427\\anaconda3\\envs\\DoT\\lib\\ssl.py", line 1341, in do_handshake\n    self._sslobj.do_handshake()\nssl.SSLZeroReturnError: TLS/SSL connection has been closed (EOF) (_ssl.c:997)\n\nDuring handling of the above exception, another exception occurred:\n\nTraceback (most recent call last):\n  File "C:\\Users\\94427\\anaconda3\\envs\\DoT\\lib\\site-packages\\urllib3\\connectionpool.py", line 793, in urlopen\n    response = self._make_request(\n  File "C:\\Users\\94427\\anaconda3\\envs\\DoT\\lib\\site-packages\\urllib3\\connectionpool.py", line 491, in _make_request\n    raise new_e\nurllib3.exceptions.SSLError: TLS/SSL connection has been closed (EOF) (_ssl.c:997)\n\nThe above exception was the direct cause of the following exception:\n\nTraceback (most recent call last):\n  File "C:\\Users\\94427\\anaconda3\\envs\\DoT\\lib\\site-packages\\requests\\adapters.py", line 486, in send\n    resp = conn.urlopen(\n  File "C:\\Users\\94427\\anaconda3\\envs\\DoT\\lib\\site-packages\\urllib3\\connectionpool.py", line 847, in urlopen\n    retries = retries.increment(\n  File "C:\\Users\\94427\\anaconda3\\envs\\DoT\\lib\\site-packages\\urllib3\\util\\retry.py", line 515, in increment\n    raise MaxRetryError(_pool, url, reason) from reason  # type: ignore[arg-type]\nurllib3.exceptions.MaxRetryError: HTTPSConnectionPool(host=\'arg-quality.debater.res.ibm.com\', port=443): Max retries exceeded with url: /score/ (Caused by SSLError(SSLZeroReturnError(6, \'TLS/SSL connection has been closed (EOF) (_ssl.c:997)\')))\n\nDuring handling of the above exception, another exception occurred:\n\nTraceback (most recent call last):\n  File "C:\\Users\\94427\\anaconda3\\envs\\DoT\\lib\\site-packages\\debater_python_api\\api\\clients\\abstract_client.py", line 65, in do_run\n    response = requests.post(url=self.host+endpoint, json=payload, headers=headers, timeout=timeout)\n  File "C:\\Users\\94427\\anaconda3\\envs\\DoT\\lib\\site-packages\\requests\\api.py", line 115, in post\n    return request("post", url, data=data, json=json, **kwargs)\n  File "C:\\Users\\94427\\anaconda3\\envs\\DoT\\lib\\site-packages\\requests\\api.py", line 59, in request\n    return session.request(method=method, url=url, **kwargs)\n  File "C:\\Users\\94427\\anaconda3\\envs\\DoT\\lib\\site-packages\\requests\\sessions.py", line 589, in request\n    resp = self.send(prep, **send_kwargs)\n  File "C:\\Users\\94427\\anaconda3\\envs\\DoT\\lib\\site-packages\\requests\\sessions.py", line 703, in send\n    r = adapter.send(request, **kwargs)\n  File "C:\\Users\\94427\\anaconda3\\envs\\DoT\\lib\\site-packages\\requests\\adapters.py", line 517, in send\n    raise SSLError(e, request=request)\nrequests.exceptions.SSLError: HTTPSConnectionPool(host=\'arg-quality.debater.res.ibm.com\', port=443): Max retries exceeded with url: /score/ (Caused by SSLError(SSLZeroReturnError(6, \'TLS/SSL connection has been closed (EOF) (_ssl.c:997)\')))\n')
  File "C:\Users\94427\kashiwa\ArgsDataset\TEST\project_debater_test.py", line 45, in <module>
    scores = argument_quality_client.run(sentence_topic_dict)[0]

  File "C:\Users\94427\anaconda3\envs\DoT\lib\site-packages\debater_python_api\api\clients\argument_quality_client.py", line 19, in run
    scores = self.run_in_batch(list_name='sentence_topic_pairs', list=pairs, other_payload={}, endpoint=endpoint, timeout=timeout)

  File "C:\Users\94427\anaconda3\envs\DoT\lib\site-packages\debater_python_api\api\clients\abstract_client.py", line 47, in run_in_batch
    batch_result = self.do_run(payload, endpoint=endpoint, timeout=timeout)

  File "C:\Users\94427\anaconda3\envs\DoT\lib\site-packages\debater_python_api\api\clients\abstract_client.py", line 85, in do_run
    raise ConnectionError(msg)


