2024-03-29 11:34:55.509176
<class 'ConnectionError'>
ConnectionError('Can\'t access server at https://arg-quality.debater.res.ibm.com/score/. Exception: urllib3.exceptions.SSLError: [SSL: UNEXPECTED_EOF_WHILE_READING] EOF occurred in violation of protocol (_ssl.c:1007)\n\nThe above exception was the direct cause of the following exception:\n\nTraceback (most recent call last):\n  File "C:\\Users\\47131\\.conda\\envs\\DoT\\lib\\site-packages\\requests\\adapters.py", line 486, in send\n    resp = conn.urlopen(\n  File "C:\\Users\\47131\\.conda\\envs\\DoT\\lib\\site-packages\\urllib3\\connectionpool.py", line 847, in urlopen\n    retries = retries.increment(\n  File "C:\\Users\\47131\\.conda\\envs\\DoT\\lib\\site-packages\\urllib3\\util\\retry.py", line 515, in increment\n    raise MaxRetryError(_pool, url, reason) from reason  # type: ignore[arg-type]\nurllib3.exceptions.MaxRetryError: HTTPSConnectionPool(host=\'arg-quality.debater.res.ibm.com\', port=443): Max retries exceeded with url: /score/ (Caused by SSLError(SSLEOFError(8, \'[SSL: UNEXPECTED_EOF_WHILE_READING] EOF occurred in violation of protocol (_ssl.c:1007)\')))\n\nDuring handling of the above exception, another exception occurred:\n\nTraceback (most recent call last):\n  File "C:\\Users\\47131\\.conda\\envs\\DoT\\lib\\site-packages\\debater_python_api\\api\\clients\\abstract_client.py", line 65, in do_run\n    response = requests.post(url=self.host+endpoint, json=payload, headers=headers, timeout=timeout)\n  File "C:\\Users\\47131\\.conda\\envs\\DoT\\lib\\site-packages\\requests\\api.py", line 115, in post\n    return request("post", url, data=data, json=json, **kwargs)\n  File "C:\\Users\\47131\\.conda\\envs\\DoT\\lib\\site-packages\\requests\\api.py", line 59, in request\n    return session.request(method=method, url=url, **kwargs)\n  File "C:\\Users\\47131\\.conda\\envs\\DoT\\lib\\site-packages\\requests\\sessions.py", line 589, in request\n    resp = self.send(prep, **send_kwargs)\n  File "C:\\Users\\47131\\.conda\\envs\\DoT\\lib\\site-packages\\requests\\sessions.py", line 703, in send\n    r = adapter.send(request, **kwargs)\n  File "C:\\Users\\47131\\.conda\\envs\\DoT\\lib\\site-packages\\requests\\adapters.py", line 517, in send\n    raise SSLError(e, request=request)\nrequests.exceptions.SSLError: HTTPSConnectionPool(host=\'arg-quality.debater.res.ibm.com\', port=443): Max retries exceeded with url: /score/ (Caused by SSLError(SSLEOFError(8, \'[SSL: UNEXPECTED_EOF_WHILE_READING] EOF occurred in violation of protocol (_ssl.c:1007)\')))\n')
  File "D:\argsdata\TEST\project_debater_test.py", line 45, in <module>
    scores = argument_quality_client.run(sentence_topic_dict)[0]

  File "C:\Users\47131\.conda\envs\DoT\lib\site-packages\debater_python_api\api\clients\argument_quality_client.py", line 19, in run
    scores = self.run_in_batch(list_name='sentence_topic_pairs', list=pairs, other_payload={}, endpoint=endpoint, timeout=timeout)

  File "C:\Users\47131\.conda\envs\DoT\lib\site-packages\debater_python_api\api\clients\abstract_client.py", line 47, in run_in_batch
    batch_result = self.do_run(payload, endpoint=endpoint, timeout=timeout)

  File "C:\Users\47131\.conda\envs\DoT\lib\site-packages\debater_python_api\api\clients\abstract_client.py", line 85, in do_run
    raise ConnectionError(msg)


