2024-03-29 12:01:30.718256
<class 'ConnectionError'>
ConnectionError('Can\'t access server at https://arg-quality.debater.res.ibm.com/score/. Exception: Traceback (most recent call last):\n  File "C:\\Users\\47131\\.conda\\envs\\DoT\\lib\\site-packages\\urllib3\\connectionpool.py", line 779, in urlopen\n    self._prepare_proxy(conn)\n  File "C:\\Users\\47131\\.conda\\envs\\DoT\\lib\\site-packages\\urllib3\\connectionpool.py", line 1048, in _prepare_proxy\n    conn.connect()\n  File "C:\\Users\\47131\\.conda\\envs\\DoT\\lib\\site-packages\\urllib3\\connection.py", line 653, in connect\n    sock_and_verified = _ssl_wrap_socket_and_match_hostname(\n  File "C:\\Users\\47131\\.conda\\envs\\DoT\\lib\\site-packages\\urllib3\\connection.py", line 806, in _ssl_wrap_socket_and_match_hostname\n    ssl_sock = ssl_wrap_socket(\n  File "C:\\Users\\47131\\.conda\\envs\\DoT\\lib\\site-packages\\urllib3\\util\\ssl_.py", line 465, in ssl_wrap_socket\n    ssl_sock = _ssl_wrap_socket_impl(sock, context, tls_in_tls, server_hostname)\n  File "C:\\Users\\47131\\.conda\\envs\\DoT\\lib\\site-packages\\urllib3\\util\\ssl_.py", line 509, in _ssl_wrap_socket_impl\n    return ssl_context.wrap_socket(sock, server_hostname=server_hostname)\n  File "C:\\Users\\47131\\.conda\\envs\\DoT\\lib\\ssl.py", line 513, in wrap_socket\n    return self.sslsocket_class._create(\n  File "C:\\Users\\47131\\.conda\\envs\\DoT\\lib\\ssl.py", line 1104, in _create\n    self.do_handshake()\n  File "C:\\Users\\47131\\.conda\\envs\\DoT\\lib\\ssl.py", line 1375, in do_handshake\n    self._sslobj.do_handshake()\nTimeoutError: _ssl.c:990: The handshake operation timed out\n\nThe above exception was the direct cause of the following exception:\n\nTraceback (most recent call last):\n  File "C:\\Users\\47131\\.conda\\envs\\DoT\\lib\\site-packages\\requests\\adapters.py", line 486, in send\n    resp = conn.urlopen(\n  File "C:\\Users\\47131\\.conda\\envs\\DoT\\lib\\site-packages\\urllib3\\connectionpool.py", line 847, in urlopen\n    retries = retries.increment(\n  File "C:\\Users\\47131\\.conda\\envs\\DoT\\lib\\site-packages\\urllib3\\util\\retry.py", line 470, in increment\n    raise reraise(type(error), error, _stacktrace)\n  File "C:\\Users\\47131\\.conda\\envs\\DoT\\lib\\site-packages\\urllib3\\util\\util.py", line 39, in reraise\n    raise value\n  File "C:\\Users\\47131\\.conda\\envs\\DoT\\lib\\site-packages\\urllib3\\connectionpool.py", line 781, in urlopen\n    self._raise_timeout(\n  File "C:\\Users\\47131\\.conda\\envs\\DoT\\lib\\site-packages\\urllib3\\connectionpool.py", line 370, in _raise_timeout\n    raise ReadTimeoutError(\nurllib3.exceptions.ReadTimeoutError: HTTPSConnectionPool(host=\'arg-quality.debater.res.ibm.com\', port=443): Read timed out. (read timeout=60)\n\nDuring handling of the above exception, another exception occurred:\n\nTraceback (most recent call last):\n  File "C:\\Users\\47131\\.conda\\envs\\DoT\\lib\\site-packages\\debater_python_api\\api\\clients\\abstract_client.py", line 65, in do_run\n    response = requests.post(url=self.host+endpoint, json=payload, headers=headers, timeout=timeout)\n  File "C:\\Users\\47131\\.conda\\envs\\DoT\\lib\\site-packages\\requests\\api.py", line 115, in post\n    return request("post", url, data=data, json=json, **kwargs)\n  File "C:\\Users\\47131\\.conda\\envs\\DoT\\lib\\site-packages\\requests\\api.py", line 59, in request\n    return session.request(method=method, url=url, **kwargs)\n  File "C:\\Users\\47131\\.conda\\envs\\DoT\\lib\\site-packages\\requests\\sessions.py", line 589, in request\n    resp = self.send(prep, **send_kwargs)\n  File "C:\\Users\\47131\\.conda\\envs\\DoT\\lib\\site-packages\\requests\\sessions.py", line 703, in send\n    r = adapter.send(request, **kwargs)\n  File "C:\\Users\\47131\\.conda\\envs\\DoT\\lib\\site-packages\\requests\\adapters.py", line 532, in send\n    raise ReadTimeout(e, request=request)\nrequests.exceptions.ReadTimeout: HTTPSConnectionPool(host=\'arg-quality.debater.res.ibm.com\', port=443): Read timed out. (read timeout=60)\n')
  File "D:\argsdata\TEST\project_debater_test.py", line 45, in <module>
    scores = argument_quality_client.run(sentence_topic_dict)[0]

  File "C:\Users\47131\.conda\envs\DoT\lib\site-packages\debater_python_api\api\clients\argument_quality_client.py", line 19, in run
    scores = self.run_in_batch(list_name='sentence_topic_pairs', list=pairs, other_payload={}, endpoint=endpoint, timeout=timeout)

  File "C:\Users\47131\.conda\envs\DoT\lib\site-packages\debater_python_api\api\clients\abstract_client.py", line 47, in run_in_batch
    batch_result = self.do_run(payload, endpoint=endpoint, timeout=timeout)

  File "C:\Users\47131\.conda\envs\DoT\lib\site-packages\debater_python_api\api\clients\abstract_client.py", line 85, in do_run
    raise ConnectionError(msg)


